Workbook

Sheet Form Responses 1
A1: Timestamp | B1: TANGGAL AWAL KEGIATAN | C1: TANGGAL AKHIR KEGIATAN | D1: NAMA KEGIATAN | E1: RUANGAN | F1: NAMA PEMINJAM | G1: Email Address
A2: 45879.833
A3: 45879.834
A4: 45879.834
A5: 45880.373
A6: 45881.422
A7: 45881.543
A8: 45881.581
A9: 45882.402
A10: 45883.423
A51: 45883.752 | B51: 45884.833 | C51: 45884.875 | D51: LATIHAN PW SM | E51: HALL RUANG SM | F51: LOVI | G51: silviarosalinda777@gmail.com
A52: 45883.754 | B52: 45884.833 | C52: 45884.875 | D52: LATIHAN SM | E52: HALL RUANG SM | F52: Lovi | G52: silviarosalinda777@gmail.com
A53: 45883.826 | B53: 45884.833 | C53: 45884.875 | D53: LAT SEKOLAH MINGGU | E53: HALL RUANG SM | F53: Silvia | G53: silviarosalinda777@gmail.com
A54: 45883.89 | B54: 45884.833 | C54: 45884.875 | D54: Lat PW sklh minggu | E54: HALL RUANG SM | F54: Silvia | G54: michael777christopher@gmail.com
A55: 45883.922 | B55: 45884.729 | C55: 45884.833 | D55: Latihan Tambourine Pely 16/8 | E55: HALL RUANG SM | F55: Grace | G55: Gracenadima@gmail.com
A56: 45888.266 | B56: 45890.75 | C56: 45890.75 | D56: Latihan PW Dgen | E56: HALL TEMPAT IBADAH | F56: Putri | G56: keziachrisant@gmail.com
A57: 45888.267 | B57: 45890.75 | C57: 45890.75 | D57: Latihan pw dgen | E57: HALL TEMPAT IBADAH | F57: Putri | G57: keziachrisant@gmail.com
A58: 45888.322 | B58: 45891.75 | C58: 45891.875 | D58: Pastor Teaching | E58: HALL TEMPAT IBADAH | F58: Candra | G58: candrawijayafb@gmail.com
A59: 45888.323 | B59: 45892.771 | C59: 45892.875 | D59: Rapat Panitia Natal | E59: HALL TEMPAT IBADAH | F59: Candra | G59: candrawijayafb@gmail.com
A60: 45888.56 | B60: 45892.792 | C60: 45892.833 | D60: Latihan pw | E60: HALL RUANG SM | F60: Brian | G60: hanjayachristian@gmail.com
A61: 45888.562 | B61: 45892.792 | C61: 45892.792 | D61: Latihan pw | E61: HALL RUANG SM | F61: Brian | G61: hanjayachristian@gmail.com
A62: 45889.66 | B62: 45891.729 | C62: 45891.771 | D62: Latihan Tim PW G8 | E62: HALL RUANG SM | F62: ELITA | G62: elitagabriel16@gmail.com
... A101: 45918.841 | B101: 45919.75 | C101: 45919.875 | D101: Fellowship PW | E101: HALL TEMPAT IBADAH | F101: Robert | G101: samariantha@gmail.com

Sheet Sheet5
A1: =IFERROR(__xludf.DUMMYFUNCTION("ARRAYFORMULA(QUERY(#REF!,""SELECT B,C,D,E,F 'ORDER BY A ASC""))"),"#REF!") -> #REF!
A5: {='Form Responses 1'!A102} | B5: {='Form Responses 1'!B102} | C5: {='Form Responses 1'!C102} | D5: {='Form Responses 1'!D102} | E5: {='Form Responses 1'!E102} | F5: {='Form Responses 1'!F102}
A6: {='Form Responses 1'!A103} | B6: {='Form Responses 1'!B103} | C6: {='Form Responses 1'!C103} | D6: {='Form Responses 1'!D103} | E6: {='Form Responses 1'!E103} | F6: {='Form Responses 1'!F103}
A7: {='Form Responses 1'!A104} | B7: {='Form Responses 1'!B104} | C7: {='Form Responses 1'!C104} | D7: {='Form Responses 1'!D104} | E7: {='Form Responses 1'!E104} | F7: {='Form Responses 1'!F104}
A8: {='Form Responses 1'!A105} | B8: {='Form Responses 1'!B105} | C8: {='Form Responses 1'!C105} | D8: {='Form Responses 1'!D105} | E8: {='Form Responses 1'!E105} | F8: {='Form Responses 1'!F105}
A9: {='Form Responses 1'!A106} | B9: {='Form Responses 1'!B106} | C9: {='Form Responses 1'!C106} | D9: {='Form Responses 1'!D106} | E9: {='Form Responses 1'!E106} | F9: {='Form Responses 1'!F106}
A10: {='Form Responses 1'!A107} | B10: {='Form Responses 1'!B107} | C10: {='Form Responses 1'!C107} | D10: {='Form Responses 1'!D107} | E10: {='Form Responses 1'!E107} | F10: {='Form Responses 1'!F107}
A11: {='Form Responses 1'!A108} | B11: {='Form Responses 1'!B108} | C11: {='Form Responses 1'!C108} | D11: {='Form Responses 1'!D108} | E11: {='Form Responses 1'!E108} | F11: {='Form Responses 1'!F108}
A12: {='Form Responses 1'!A109} | B12: {='Form Responses 1'!B109} | C12: {='Form Responses 1'!C109} | D12: {='Form Responses 1'!D109} | E12: {='Form Responses 1'!E109} | F12: {='Form Responses 1'!F109}
A13: {='Form Responses 1'!A110} | B13: {='Form Responses 1'!B110} | C13: {='Form Responses 1'!C110} | D13: {='Form Responses 1'!D110} | E13: {='Form Responses 1'!E110} | F13: {='Form Responses 1'!F110}
A14: {='Form Responses 1'!A111} | B14: {='Form Responses 1'!B111} | C14: {='Form Responses 1'!C111} | D14: {='Form Responses 1'!D111} | E14: {='Form Responses 1'!E111} | F14: {='Form Responses 1'!F111}
A15: {='Form Responses 1'!A112} | B15: {='Form Responses 1'!B112} | C15: {='Form Responses 1'!C112} | D15: {='Form Responses 1'!D112} | E15: {='Form Responses 1'!E112} | F15: {='Form Responses 1'!F112}
A16: {='Form Responses 1'!A113} | B16: {='Form Responses 1'!B113} | C16: {='Form Responses 1'!C113} | D16: {='Form Responses 1'!D113} | E16: {='Form Responses 1'!E113} | F16: {='Form Responses 1'!F113}
... A27: {='Form Responses 1'!A124} | B27: {='Form Responses 1'!B124} | C27: {='Form Responses 1'!C124} | D27: {='Form Responses 1'!D124} | E27: {='Form Responses 1'!E124} | F27: {='Form Responses 1'!F124}
B28: {='Form Responses 1'!B125} | C28: {='Form Responses 1'!C125} | D28: {='Form Responses 1'!D125} | E28: {='Form Responses 1'!E125} | F28: {='Form Responses 1'!F125}
B29: {='Form Responses 1'!B126} | C29: {='Form Responses 1'!C126} | D29: {='Form Responses 1'!D126} | E29: {='Form Responses 1'!E126} | F29: {='Form Responses 1'!F126}
B30: {='Form Responses 1'!B127} | C30: {='Form Responses 1'!C127} | D30: {='Form Responses 1'!D127} | E30: {='Form Responses 1'!E127} | F30: {='Form Responses 1'!F127}
B31: {='Form Responses 1'!B128} | C31: {='Form Responses 1'!C128} | D31: {='Form Responses 1'!D128} | E31: {='Form Responses 1'!E128} | F31: {='Form Responses 1'!F128}
B32: {='Form Responses 1'!B129} | C32: {='Form Responses 1'!C129} | D32: {='Form Responses 1'!D129} | E32: {='Form Responses 1'!E129} | F32: {='Form Responses 1'!F129}
B33: {='Form Responses 1'!B130} | C33: {='Form Responses 1'!C130} | D33: {='Form Responses 1'!D130} | E33: {='Form Responses 1'!E130}
B34: {='Form Responses 1'!B131} | C34: {='Form Responses 1'!C131} | D34: {='Form Responses 1'!D131} | E34: {='Form Responses 1'!E131}
B35: {='Form Responses 1'!B132} | C35: {='Form Responses 1'!C132} | D35: {='Form Responses 1'!D132} | E35: {='Form Responses 1'!E132}
B36: {='Form Responses 1'!B133} | C36: {='Form Responses 1'!C133} | D36: {='Form Responses 1'!D133}
B37: {='Form Responses 1'!B134} | C37: {='Form Responses 1'!C134} | D37: {='Form Responses 1'!D134}
B38: {='Form Responses 1'!B135} | C38: {='Form Responses 1'!C135} | D38: {='Form Responses 1'!D135}
B39: {='Form Responses 1'!B136} | C39: {='Form Responses 1'!C136} | D39: {='Form Responses 1'!D136}
B40: {='Form Responses 1'!B137} | C40: {='Form Responses 1'!C137} | D40: {='Form Responses 1'!D137}
B41: {='Form Responses 1'!B138} | C41: {='Form Responses 1'!C138} | D41: {='Form Responses 1'!D138}
B42: {='Form Responses 1'!B139} | C42: {='Form Responses 1'!C139} | D42: {='Form Responses 1'!D139}
B43: {='Form Responses 1'!B140} | C43: {='Form Responses 1'!C140} | D43: {='Form Responses 1'!D140}
B44: {='Form Responses 1'!B141} | C44: {='Form Responses 1'!C141} | D44: {='Form Responses 1'!D141}
B45: {='Form Responses 1'!B142} | C45: {='Form Responses 1'!C142}
B46: {='Form Responses 1'!B143} | C46: {='Form Responses 1'!C143}
B47: {='Form Responses 1'!B144} | C47: {='Form Responses 1'!C144}
B48: {='Form Responses 1'!B145} | C48: {='Form Responses 1'!C145}
B49: {='Form Responses 1'!B146} | C49: {='Form Responses 1'!C146}
B50: {='Form Responses 1'!B147} | C50: {='Form Responses 1'!C147}
B51: {='Form Responses 1'!B148}
B52: {='Form Responses 1'!B149}
B53: {='Form Responses 1'!B150}
...
